<?xml version="1.0" ?>
<!-- =================================================================================== -->
<!-- |    This document was autogenerated by xacro from car.xacro                      | -->
<!-- |    EDITING THIS FILE BY HAND IS NOT RECOMMENDED                                 | -->
<!-- =================================================================================== -->
<robot name="car">
  <gazebo reference="chassis">
    <material>CarMaterial</material>
  </gazebo>
  <link name="base_link">
    <parent link="odom"/>
    <visual>
      <geometry>
        <box size="0.01 0.01 0.01"/>
      </geometry>
      <material name="chassis_mat"/>
    </visual>
  </link>
  <joint name="base_link_to_chassis" type="fixed">
    <origin rpy="0 0 0" xyz="0.476 0 0.3"/>
    <parent link="base_link"/>
    <child link="chassis"/>
  </joint>
  <link name="chassis">
    <collision>
      <origin rpy="0 0 0" xyz="0 0 0.27"/>
      <geometry>
        <box size="1.56 0.4 0.39999999999999997"/>
      </geometry>
    </collision>
    <visual>
      <origin rpy="0 0 0" xyz="0 0 0"/>
      <geometry>
        <mesh filename="file:///home/master/Desktop/II_last_semester/Laba_2/meshes/car.dae"/>
      </geometry>
    </visual>
    <inertial>
      <mass value="0.001"/>
      <inertia ixx="0.001" ixy="0" ixz="0" iyy="0.001" iyz="0" izz="0.001"/>
    </inertial>
  </link>
  <joint name="front_left_steering_knuckle_joint" type="revolute">
    <origin rpy="0 0 1.5707963267948966" xyz="0.47600000000000003 0.4 -0.3"/>
    <parent link="chassis"/>
    <child link="front_left_steering_knuckle_link"/>
    <axis xyz="0 0 1"/>
    <limit effort="1.25" lower="-0.5" upper="0.5" velocity="2.0"/>
  </joint>
  <transmission name="front_left_wheel_steering">
    <type>transmission_interface/SimpleTransmission</type>
    <joint name="front_left_steering_knuckle_joint">
      <hardwareInterface>PositionJointInterface</hardwareInterface>
    </joint>
    <actuator name="front_left_wheel_steering_act">
      <hardwareInterface>hardware_interface/PositionJointInterface</hardwareInterface>
    </actuator>
  </transmission>
  <link name="front_left_steering_knuckle_link">
    <visual>
      <origin rpy="0 0 0" xyz="0 0 0"/>
      <geometry>
        <sphere radius="0.01"/>
      </geometry>
      <material name="white"/>
    </visual>
    <inertial>
      <mass value="0.001"/>
      <inertia ixx="0.001" ixy="0" ixz="0" iyy="0.001" iyz="0" izz="0.001"/>
    </inertial>
  </link>
  <joint name="front_right_steering_knuckle_joint" type="revolute">
    <origin rpy="0 0 1.5707963267948966" xyz="0.47600000000000003 -0.4 -0.3"/>
    <parent link="chassis"/>
    <child link="front_right_steering_knuckle_link"/>
    <axis xyz="0 0 1"/>
    <limit effort="1.25" lower="-0.5" upper="0.5" velocity="2.0"/>
  </joint>
  <transmission name="front_right_wheel_steering">
    <type>transmission_interface/SimpleTransmission</type>
    <joint name="front_right_steering_knuckle_joint">
      <hardwareInterface>PositionJointInterface</hardwareInterface>
    </joint>
    <actuator name="front_right_wheel_steering_act">
      <hardwareInterface>hardware_interface/PositionJointInterface</hardwareInterface>
    </actuator>
  </transmission>
  <link name="front_right_steering_knuckle_link">
    <visual>
      <origin rpy="0 0 0" xyz="0 0 0"/>
      <geometry>
        <sphere radius="0.01"/>
      </geometry>
      <material name="white"/>
    </visual>
    <inertial>
      <mass value="0.001"/>
      <inertia ixx="0.001" ixy="0" ixz="0" iyy="0.001" iyz="0" izz="0.001"/>
    </inertial>
  </link>
  <joint name="rear_left_steering_knuckle_joint" type="fixed">
    <origin rpy="0 0 1.5707963267948966" xyz="-0.47600000000000003 0.4 -0.3"/>
    <parent link="chassis"/>
    <child link="rear_left_steering_knuckle_link"/>
  </joint>
  <link name="rear_left_steering_knuckle_link">
    <visual>
      <origin rpy="0 0 0" xyz="0 0 0"/>
      <geometry>
        <sphere radius="0.01"/>
      </geometry>
      <material name="white"/>
    </visual>
    <inertial>
      <mass value="0.001"/>
      <inertia ixx="0.001" ixy="0" ixz="0" iyy="0.001" iyz="0" izz="0.001"/>
    </inertial>
  </link>
  <joint name="rear_right_steering_knuckle_joint" type="fixed">
    <origin rpy="0 0 1.5707963267948966" xyz="-0.47600000000000003 -0.4 -0.3"/>
    <parent link="chassis"/>
    <child link="rear_right_steering_knuckle_link"/>
  </joint>
  <link name="rear_right_steering_knuckle_link">
    <visual>
      <origin rpy="0 0 0" xyz="0 0 0"/>
      <geometry>
        <sphere radius="0.01"/>
      </geometry>
      <material name="white"/>
    </visual>
    <inertial>
      <mass value="0.001"/>
      <inertia ixx="0.001" ixy="0" ixz="0" iyy="0.001" iyz="0" izz="0.001"/>
    </inertial>
  </link>
  <joint name="front_left_axel_joint" type="fixed">
    <origin rpy="0 0 0" xyz="0 0 0"/>
    <parent link="front_left_steering_knuckle_link"/>
    <child link="front_left_wheel_axel"/>
  </joint>
  <link name="front_left_wheel_axel">
    <visual>
      <origin rpy="0 0 0" xyz="0 0 0"/>
      <geometry>
        <sphere radius="0.01"/>
      </geometry>
      <material name="white"/>
    </visual>
    <inertial>
      <mass value="0.001"/>
      <inertia ixx="0.001" ixy="0" ixz="0" iyy="0.001" iyz="0" izz="0.001"/>
    </inertial>
  </link>
  <joint name="front_left_wheel_joint" type="continuous">
    <origin rpy="0 0 0" xyz="0 0 0"/>
    <parent link="front_left_wheel_axel"/>
    <child link="front_left_wheel_link"/>
    <axis xyz="1 0 0"/>
    <limit effort="100000.0" velocity="255.0"/>
  </joint>
  <transmission name="front_left_wheel_vel">
    <type>transmission_interface/SimpleTransmission</type>
    <joint name="front_left_wheel_joint">
      <hardwareInterface>VelocityJointInterface</hardwareInterface>
    </joint>
    <actuator name="front_left_wheel_vel_act">
      <hardwareInterface>hardware_interface/VelocityJointInterface</hardwareInterface>
    </actuator>
  </transmission>
  <link name="front_left_wheel_link">
    <collision>
      <origin rpy="0 1.5707963267948966 0" xyz="0 0 0"/>
      <geometry>
        <cylinder length="0.2" radius="0.2"/>
      </geometry>
    </collision>
    <visual>
      <origin rpy="0 1.5707963267948966 0" xyz="0 0 0"/>
      <geometry>
        <cylinder length="0.2" radius="0.2"/>
      </geometry>
    </visual>
    <inertial>
      <origin rpy="0 0 0" xyz="0 0 0"/>
      <mass value="2.0"/>
      <inertia ixx="0.04000000000000001" ixy="0" ixz="0" iyy="0.026666666666666672" iyz="0" izz="0.026666666666666672"/>
    </inertial>
  </link>
  <joint name="front_right_axel_joint" type="fixed">
    <origin rpy="0 0 0" xyz="0 0 0"/>
    <parent link="front_right_steering_knuckle_link"/>
    <child link="front_right_wheel_axel"/>
  </joint>
  <link name="front_right_wheel_axel">
    <visual>
      <origin rpy="0 0 0" xyz="0 0 0"/>
      <geometry>
        <sphere radius="0.01"/>
      </geometry>
      <material name="white"/>
    </visual>
    <inertial>
      <mass value="0.001"/>
      <inertia ixx="0.001" ixy="0" ixz="0" iyy="0.001" iyz="0" izz="0.001"/>
    </inertial>
  </link>
  <joint name="front_right_wheel_joint" type="continuous">
    <origin rpy="0 0 0" xyz="0 0 0"/>
    <parent link="front_right_wheel_axel"/>
    <child link="front_right_wheel_link"/>
    <axis xyz="1 0 0"/>
    <limit effort="100000.0" velocity="255.0"/>
  </joint>
  <transmission name="front_right_wheel_vel">
    <type>transmission_interface/SimpleTransmission</type>
    <joint name="front_right_wheel_joint">
      <hardwareInterface>VelocityJointInterface</hardwareInterface>
    </joint>
    <actuator name="front_right_wheel_vel_act">
      <hardwareInterface>hardware_interface/VelocityJointInterface</hardwareInterface>
    </actuator>
  </transmission>
  <link name="front_right_wheel_link">
    <collision>
      <origin rpy="0 1.5707963267948966 0" xyz="0 0 0"/>
      <geometry>
        <cylinder length="0.2" radius="0.2"/>
      </geometry>
    </collision>
    <visual>
      <origin rpy="0 1.5707963267948966 0" xyz="0 0 0"/>
      <geometry>
        <cylinder length="0.2" radius="0.2"/>
      </geometry>
    </visual>
    <inertial>
      <origin rpy="0 0 0" xyz="0 0 0"/>
      <mass value="2.0"/>
      <inertia ixx="0.04000000000000001" ixy="0" ixz="0" iyy="0.026666666666666672" iyz="0" izz="0.026666666666666672"/>
    </inertial>
  </link>
  <joint name="rear_left_axel_joint" type="fixed">
    <origin rpy="0 0 0" xyz="0 0 0"/>
    <parent link="rear_left_steering_knuckle_link"/>
    <child link="rear_left_wheel_axel"/>
  </joint>
  <link name="rear_left_wheel_axel">
    <visual>
      <origin rpy="0 0 0" xyz="0 0 0"/>
      <geometry>
        <sphere radius="0.01"/>
      </geometry>
      <material name="white"/>
    </visual>
    <inertial>
      <mass value="0.001"/>
      <inertia ixx="0.001" ixy="0" ixz="0" iyy="0.001" iyz="0" izz="0.001"/>
    </inertial>
  </link>
  <joint name="rear_left_wheel_joint" type="continuous">
    <origin rpy="0 0 0" xyz="0 0 0"/>
    <parent link="rear_left_wheel_axel"/>
    <child link="rear_left_wheel_link"/>
    <axis xyz="1 0 0"/>
    <limit effort="100000.0" velocity="255.0"/>
  </joint>
  <link name="rear_left_wheel_link">
    <collision>
      <origin rpy="0 1.5707963267948966 0" xyz="0 0 0"/>
      <geometry>
        <cylinder length="0.2" radius="0.2"/>
      </geometry>
    </collision>
    <visual>
      <origin rpy="0 1.5707963267948966 0" xyz="0 0 0"/>
      <geometry>
        <cylinder length="0.2" radius="0.2"/>
      </geometry>
    </visual>
    <inertial>
      <origin rpy="0 0 0" xyz="0 0 0"/>
      <mass value="2.0"/>
      <inertia ixx="0.04000000000000001" ixy="0" ixz="0" iyy="0.026666666666666672" iyz="0" izz="0.026666666666666672"/>
    </inertial>
  </link>
  <joint name="rear_right_axel_joint" type="fixed">
    <origin rpy="0 0 0" xyz="0 0 0"/>
    <parent link="rear_right_steering_knuckle_link"/>
    <child link="rear_right_wheel_axel"/>
  </joint>
  <link name="rear_right_wheel_axel">
    <visual>
      <origin rpy="0 0 0" xyz="0 0 0"/>
      <geometry>
        <sphere radius="0.01"/>
      </geometry>
      <material name="white"/>
    </visual>
    <inertial>
      <mass value="0.001"/>
      <inertia ixx="0.001" ixy="0" ixz="0" iyy="0.001" iyz="0" izz="0.001"/>
    </inertial>
  </link>
  <joint name="rear_right_wheel_joint" type="continuous">
    <origin rpy="0 0 0" xyz="0 0 0"/>
    <parent link="rear_right_wheel_axel"/>
    <child link="rear_right_wheel_link"/>
    <axis xyz="1 0 0"/>
    <limit effort="100000.0" velocity="255.0"/>
  </joint>
  <link name="rear_right_wheel_link">
    <collision>
      <origin rpy="0 1.5707963267948966 0" xyz="0 0 0"/>
      <geometry>
        <cylinder length="0.2" radius="0.2"/>
      </geometry>
    </collision>
    <visual>
      <origin rpy="0 1.5707963267948966 0" xyz="0 0 0"/>
      <geometry>
        <cylinder length="0.2" radius="0.2"/>
      </geometry>
    </visual>
    <inertial>
      <origin rpy="0 0 0" xyz="0 0 0"/>
      <mass value="2.0"/>
      <inertia ixx="0.04000000000000001" ixy="0" ixz="0" iyy="0.026666666666666672" iyz="0" izz="0.026666666666666672"/>
    </inertial>
  </link>
  <gazebo>
    <plugin filename="libgazebo_ros_control.so" name="gazebo_ros_control"/>
  </gazebo>
  <joint name="hokuyo_joint" type="fixed">
    <axis xyz="0 0 0"/>
    <origin rpy="0 0 0" xyz="0.574 0 0.72"/>
    <parent link="base_link"/>
    <child link="hokuyo"/>
  </joint>
  <!-- Hokuyo Laser -->
  <link name="hokuyo">
    <collision>
      <origin rpy="0 0 0" xyz="0 0 0"/>
      <geometry>
        <box size="0.1 0.1 0.1"/>
      </geometry>
    </collision>
    <visual>
      <origin rpy="0 0 0" xyz="0 0 0"/>
      <geometry>
        <mesh filename="file:///home/master/Desktop/II_last_semester/Laba_2/meshes/hokuyo.dae"/>
      </geometry>
    </visual>
    <inertial>
      <mass value="1e-5"/>
      <origin rpy="0 0 0" xyz="0 0 0"/>
      <inertia ixx="1e-6" ixy="0" ixz="0" iyy="1e-6" iyz="0" izz="1e-6"/>
    </inertial>
  </link>
  <!-- hokuyo -->
  <gazebo reference="hokuyo">
    <sensor name="head_hokuyo_sensor" type="gpu_ray">
      <pose>0 0 0 0 0 0</pose>
      <visualize>false</visualize>
      <update_rate>40</update_rate>
      <ray>
        <scan>
          <horizontal>
            <samples>1080</samples>
            <resolution>1</resolution>
            <min_angle>-2,35619</min_angle>
            <max_angle>2,35619</max_angle>
          </horizontal>
        </scan>
        <range>
          <min>0.1</min>
          <max>30.0</max>
          <resolution>0.005</resolution>
        </range>
        <noise>
          <type>gaussian</type>
          <!-- Noise parameters based on published spec for Hokuyo laser
               achieving "+-30mm" accuracy at range < 10m.  A mean of 0.0m and
               stddev of 0.01m will put 99.7% of samples within 0.03m of the true
               reading. -->
          <mean>0.0</mean>
          <stddev>0.01</stddev>
        </noise>
      </ray>
      <plugin filename="libgazebo_ros_gpu_laser.so" name="gazebo_ros_head_hokuyo_controller">
        <topicName>/scan</topicName>
        <frameName>hokuyo</frameName>
      </plugin>
    </sensor>
  </gazebo>
  <gazebo>
    <plugin filename="libgazebo_ros_p3d.so" name="publisher_fake_odom">
      <updateRate>100.0</updateRate>
      <bodyName>base_link</bodyName>
      <topicName>odom_truth</topicName>
      <gaussianNoise>0.0</gaussianNoise>
      <frameName>map</frameName>
    </plugin>
  </gazebo>
</robot>
